Workbook
Name CNG: Dropdowns!$I$2:$I$4
Name Commercial_and_Industrial_Waste: Dropdowns!$A$2:$A$4
Name Diesel: Dropdowns!$H$2:$H$4
Name Food_and_Drink_Waste: Dropdowns!$C$2:$C$5
Name Garden_Waste: Dropdowns!$C$2:$C$5
Name Household_Residue: Dropdowns!$A$2:$A$4
Name Large_Sized_Car: Dropdowns!$C$14:$C$17
Name LPG: Dropdowns!$F$2:$F$4
Name Medium_Sized_Car: Dropdowns!$C$14:$C$17
Name Personal: Dropdowns!$B$7:$B$10
Name Petrol_Gasoline: Dropdowns!$E$2:$E$4
Name PNG: Dropdowns!$G$2:$G$4
Name Public: Dropdowns!$A$7:$A$8
Name Small_Sized_Car: Dropdowns!$B$14:$B$16

Sheet Fossil Fuel
A1: Compulsory
A2: Optional
A3: Either fill this
A4: Or this
A5: Don't Fill This
A6: Enter the serial number | B6: Select the facility name from the dropdown | C6: Enter the year for this data instance | D6: Select the month for this data instance | E6: Select the fuel used from the dropdown | F6: Select the unit of the fuel used | G6: Enter the amount of fuel used
A7: Sr. No. | B7: Facility Name | C7: Year | D7: Month | E7: Fuel Type | F7: Unit | G7: Amount
A8: 1 | B8: Shops, Bank and PO | C8: 2023 | D8: June | E8: Petrol/Gasoline | F8: kg | G8: 629
A9: 2 | B9: Visitor's Hostel | C9: 2024 | D9: January | E9: Diesel | F9: kg | G9: 496
A10: 3 | B10: Lawns and Horticulture | C10: 2023 | D10: October | E10: PNG | F10: kg | G10: 335
A11: 4 | B11: Hostels | C11: 2024 | D11: February | E11: CNG | F11: kg | G11: 949
A12: 5 | B12: Hostels | C12: 2024 | D12: January | E12: Diesel | F12: kg | G12: 896
A13: 6 | B13: Visitor's Hostel | C13: 2023 | D13: October | E13: PNG | F13: kg | G13: 313
A14: 7 | B14: Others | C14: 2024 | D14: April | E14: CNG | F14: kg | G14: 359
A15: 8 | B15: Academic Area | C15: 2023 | D15: October | E15: PNG | F15: kg | G15: 862
A16: 9 | B16: Visitor's Hostel | C16: 2024 | D16: March | E16: CNG | F16: kg | G16: 630
A17: 10 | B17: Hostels | C17: 2024 | D17: September | E17: PNG | F17: kg | G17: 717
A18: 11 | B18: Shops, Bank and PO | C18: 2022 | D18: September | E18: Diesel | F18: kg | G18: 501
A19: 12 | B19: Residential Areas | C19: 2023 | D19: May | E19: Petrol/Gasoline | F19: kg | G19: 263
... A38: 31 | B38: Shops, Bank and PO | C38: 2022 | D38: June | E38: CNG | F38: kg | G38: 139

Sheet Fugitive
B1: Compulsory
B2: Optional
B3: Either fill this
B4: Or this
B5: Don’t Fill This
A6: Enter the serial number | B6: Select the facility name from the dropdown | C6: Enter the year for this data instance | D6: Select the month for this data instance | E6: Choose The Application Type | F6: Enter The Number of Units
A7: Sr. No. | B7: Facility Name | C7: Year | D7: Month | E7: Application Type | F7: Number of Units
A8: 1 | B8: Servant's Quarters | C8: 2024 | D8: October | E8: Commercial Refrigeration | F8: 10
A9: 2 | B9: Academic Area | C9: 2024 | D9: February | E9: Industrial Refrigeration | F9: 8
A10: 3 | B10: Others | C10: 2024 | D10: July | E10: Residential and Commercial A/Cs | F10: 1
A11: 4 | B11: Residential Areas | C11: 2022 | D11: June | E11: Commercial Refrigeration | F11: 3
A12: 5 | B12: Servant's Quarters | C12: 2023 | D12: December | E12: Industrial Refrigeration | F12: 5
A13: 6 | B13: Others | C13: 2022 | D13: November | E13: Residential and Commercial A/Cs | F13: 8
A14: 7 | B14: Schools | C14: 2022 | D14: June | E14: Domestic Refrigeration | F14: 11
A15: 8 | B15: Schools | C15: 2024 | D15: September | E15: Domestic Refrigeration | F15: 3
A16: 9 | B16: Dhobhighat | C16: 2022 | D16: February | E16: Commercial Refrigeration | F16: 11
A17: 10 | B17: Dhobhighat | C17: 2023 | D17: May | E17: Commercial Refrigeration | F17: 5
A18: 11 | B18: Shops, Bank and PO | C18: 2022 | D18: December | E18: Industrial Refrigeration | F18: 4
A19: 12 | B19: Shops, Bank and PO | C19: 2022 | D19: October | E19: Residential and Commercial A/Cs | F19: 12
... A38: 31 | B38: Lawns and Horticulture | C38: 2024 | D38: June | E38: Domestic Refrigeration | F38: 5

Sheet Electricity
B1: Compulsory
B2: Either fill this
B3: Or this
B4: Don’t Fill This
A5: Enter the serial number | B5: Select the facility name from the dropdown | C5: Enter the year for this data instance | D5: Enter the month for this data instance | E5: Select the type of electricity used | F5: Select the source of production of the used electricity | G5: Select the unit of used electricity | H5: Enter the amount of electricity used in the selected unit
A6: Sr. No. | B6: Facility Name | C6: Year | D6: Month | E6: Type | F6: Source | G6: Unit | H6: Amount/Quantity
A7: 1 | B7: Schools | C7: 2024 | D7: April | E7: Coal/Thermal | F7: Purchased | G7: kWH | H7: 13594
A8: 2 | B8: Others | C8: 2024 | D8: January | E8: Coal/Thermal | F8: Purchased | G8: kWH | H8: 7731
A9: 3 | B9: Shops, Bank and PO | C9: 2023 | D9: July | E9: Coal/Thermal | F9: Purchased | G9: kWH | H9: 8988
A10: 4 | B10: Schools | C10: 2023 | D10: March | E10: Coal/Thermal | F10: Purchased | G10: kWH | H10: 15283
A11: 5 | B11: Others | C11: 2024 | D11: March | E11: Coal/Thermal | F11: Purchased | G11: kWH | H11: 15258
A12: 6 | B12: Servant's Quarters | C12: 2022 | D12: May | E12: Solar | F12: Self-Produced | G12: kWH | H12: 9439
A13: 7 | B13: Dhobhighat | C13: 2024 | D13: August | E13: Coal/Thermal | F13: Purchased | G13: kWH | H13: 8040
A14: 8 | B14: Dhobhighat | C14: 2022 | D14: March | E14: Coal/Thermal | F14: Purchased | G14: kWH | H14: 13073
A15: 9 | B15: Dhobhighat | C15: 2022 | D15: July | E15: Coal/Thermal | F15: Purchased | G15: kWH | H15: 1573
A16: 10 | B16: Others | C16: 2022 | D16: October | E16: Solar | F16: Self-Produced | G16: kWH | H16: 10225
A17: 11 | B17: Academic Area | C17: 2023 | D17: August | E17: Coal/Thermal | F17: Purchased | G17: kWH | H17: 12412
A18: 12 | B18: Others | C18: 2022 | D18: September | E18: Coal/Thermal | F18: Purchased | G18: kWH | H18: 7051
... A37: 31 | B37: Visitor's Hostel | C37: 2022 | D37: March | E37: Coal/Thermal | F37: Purchased | G37: kWH | H37: 8525

Sheet Water
B1: Compulsory
B2: Optional
B3: Either fill this
B4: Or this
B5: Don’t Fill This
A6: Enter the serial number | B6: Select the facility name from the dropdown | C6: Enter the year for this data instance | D6: Select the month for this data instance | E6: Select whether the water is supplied or treated | F6: Select the withdrawal source or the discharged site of the supplied/treated water | G6: Select the unit of volume | H6: Enter the quantity
A7: Sr. No. | B7: Facility Name | C7: Year | D7: Month | E7: Type | F7: Withdrawal Source / Discharge Site | G7: Unit | H7: Quantity
A8: 1 | B8: Residential Areas | C8: 2024 | D8: October | E8: Supplied Water | F8: Overhead Tank | G8: cubic metre | H8: 1344
A9: 2 | B9: Health Centre | C9: 2022 | D9: March | E9: Supplied Water | F9: Overhead Tank | G9: cubic metre | H9: 1523
A10: 3 | B10: Shops, Bank and PO | C10: 2024 | D10: November | E10: Supplied Water | F10: Municipal Supply | G10: cubic metre | H10: 1248
A11: 4 | B11: Schools | C11: 2022 | D11: August | E11: Treated Water | F11: Recycled Water Outlet | G11: cubic metre | H11: 453
A12: 5 | B12: Dhobhighat | C12: 2023 | D12: October | E12: Supplied Water | F12: Overhead Tank | G12: cubic metre | H12: 1122
A13: 6 | B13: Academic Area | C13: 2022 | D13: July | E13: Supplied Water | F13: Municipal Supply | G13: cubic metre | H13: 1405
A14: 7 | B14: Schools | C14: 2022 | D14: December | E14: Supplied Water | F14: Overhead Tank | G14: cubic metre | H14: 2322
A15: 8 | B15: Schools | C15: 2022 | D15: November | E15: Treated Water | F15: Municipal Drain | G15: cubic metre | H15: 267
A16: 9 | B16: Residential Areas | C16: 2024 | D16: October | E16: Supplied Water | F16: Overhead Tank | G16: cubic metre | H16: 862
A17: 10 | B17: Servant's Quarters | C17: 2023 | D17: January | E17: Treated Water | F17: Municipal Drain | G17: cubic metre | H17: 1741
A18: 11 | B18: Shops, Bank and PO | C18: 2022 | D18: June | E18: Treated Water | F18: Sewage Treatment Plant | G18: cubic metre | H18: 1857
A19: 12 | B19: Servant's Quarters | C19: 2024 | D19: April | E19: Supplied Water | F19: Municipal Supply | G19: cubic metre | H19: 1610
... A38: 31 | B38: Visitor's Hostel | C38: 2022 | D38: February | E38: Treated Water | F38: Sewage Treatment Plant | G38: cubic metre | H38: 2357

Sheet Waste
B1: Compulsory
B2: Optional
B3: Either fill this
B4: Or this
B5: Don’t Fill This
A6: Enter the serial number | B6: Select the facility name from the dropdown | C6: Enter the year for this data instance | D6: Select the month for this data instance | E6: Select the Waste Type | F6: Select the Waste Treatment Type | G6: Select the unit of volume | H6: Enter the quantity
A7: Sr. No. | B7: Facility Name | C7: Year | D7: Month | E7: Waste Type | F7: Waste Treatment Type | G7: Unit | H7: Quantity
A8: 1 | B8: Residential Areas | C8: 2024 | D8: February | E8: Food and Drink Waste | F8: Composting | G8: kg | H8: 492
A9: 2 | B9: Visitor's Hostel | C9: 2023 | D9: August | E9: Commercial and Industrial Waste | F9: Combustion | G9: kg | H9: 799
A10: 3 | B10: Hostels | C10: 2022 | D10: September | E10: Food and Drink Waste | F10: Composting | G10: kg | H10: 151
A11: 4 | B11: Schools | C11: 2024 | D11: August | E11: Garden Waste | F11: Composting | G11: kg | H11: 123
A12: 5 | B12: Lawns and Horticulture | C12: 2023 | D12: March | E12: Commercial and Industrial Waste | F12: Landfills | G12: kg | H12: 205
A13: 6 | B13: Health Centre | C13: 2022 | D13: September | E13: Commercial and Industrial Waste | F13: Recycling | G13: kg | H13: 567
A14: 7 | B14: Academic Area | C14: 2024 | D14: September | E14: Garden Waste | F14: Recycling | G14: kg | H14: 448
A15: 8 | B15: Hostels | C15: 2022 | D15: November | E15: Commercial and Industrial Waste | F15: Combustion | G15: kg | H15: 120
A16: 9 | B16: Hostels | C16: 2024 | D16: April | E16: Commercial and Industrial Waste | F16: Recycling | G16: kg | H16: 412
A17: 10 | B17: Others | C17: 2023 | D17: May | E17: Household Residue | F17: Landfills | G17: kg | H17: 116
A18: 11 | B18: Shops, Bank and PO | C18: 2022 | D18: September | E18: Household Residue | F18: Recycling | G18: kg | H18: 737
A19: 12 | B19: Health Centre | C19: 2024 | D19: July | E19: Household Residue | F19: Combustion | G19: kg | H19: 102
... A38: 31 | B38: Visitor's Hostel | C38: 2022 | D38: October | E38: Commercial and Industrial Waste | F38: Combustion | G38: kg | H38: 110

Sheet Travel
B1: Compulsory
B2: Optional
B3: Either fill this
B4: Or this
B5: Don’t Fill This
A6: Enter the serial number | B6: Select the facility name from the dropdown | C6: Enter the year for this data instance | D6: Select the month for this data instance | E6: Select the Mode of Transport | F6: Select the type of Rail | G6: Select the Length of Flight | H6: Select The Vehicle Ownership | I6: Select The Vehicle Type | J6: Select The Fuel Type | K6: Enter the Distance Travelled in KM
A7: Sr. No. | B7: Facility Name | C7: Year | D7: Month | E7: Mode of Transport | F7: Rail Type | G7: Length of Flight | H7: Vehicle Ownership | I7: Vehicle Type | J7: Fuel Type | K7: Distance Travelled (KM)
A8: 1 | B8: Schools | C8: 2024 | D8: June | E8: Airways | G8: International | K8: 4476
A9: 2 | B9: Lawns and Horticulture | C9: 2024 | D9: August | E9: Roadways | H9: Public | I9: Taxi | K9: 7
A10: 3 | B10: Hostels | C10: 2022 | D10: July | E10: Railways | F10: National Railways | K10: 498
A11: 4 | B11: Dhobhighat | C11: 2023 | D11: October | E11: Roadways | H11: Public | I11: Taxi | K11: 44
A12: 5 | B12: Health Centre | C12: 2024 | D12: October | E12: Railways | F12: National Railways | K12: 1207
A13: 6 | B13: Hostels | C13: 2024 | D13: March | E13: Roadways | H13: Public | I13: Bus | K13: 71
A14: 7 | B14: Health Centre | C14: 2022 | D14: March | E14: Airways | G14: Long Haul | K14: 6352
A15: 8 | B15: Dhobhighat | C15: 2023 | D15: May | E15: Roadways | H15: Public | I15: Bus | K15: 24
A16: 9 | B16: Dhobhighat | C16: 2024 | D16: August | E16: Airways | G16: Long Haul | K16: 6353
A17: 10 | B17: Residential Areas | C17: 2024 | D17: June | E17: Railways | F17: National Railways | K17: 394
A18: 11 | B18: Lawns and Horticulture | C18: 2023 | D18: October | E18: Airways | G18: Domestic | K18: 1177
A19: 12 | B19: Health Centre | C19: 2024 | D19: November | E19: Airways | G19: International | K19: 3874
A20: 13 | B20: Lawns and Horticulture | C20: 2024 | D20: December | E20: Railways | F20: Metro | K20: 341
A21: 14 | B21: Shops, Bank and PO | C21: 2022 | D21: March | E21: Airways | G21: Short Haul | K21: 1512
A22: 15 | B22: Shops, Bank and PO | C22: 2024 | D22: January | E22: Airways | G22: Short Haul | K22: 1085
A23: 16 | B23: Schools | C23: 2022 | D23: March | E23: Roadways | H23: Public | I23: Bus | K23: 110
A24: 17 | B24: Visitor's Hostel | C24: 2023 | D24: October | E24: Roadways | H24: Public | I24: Taxi | K24: 77
A25: 18 | B25: Schools | C25: 2022 | D25: March | E25: Railways | F25: Metro | K25: 1469
A26: 19 | B26: Visitor's Hostel | C26: 2023 | D26: March | E26: Railways | F26: National Railways | K26: 610
A27: 20 | B27: Others | C27: 2023 | D27: October | E27: Roadways | H27: Public | I27: Taxi | K27: 113
A28: 21 | B28: Health Centre | C28: 2024 | D28: January | E28: Airways | G28: Long Haul | K28: 6590
A29: 22 | B29: Servant's Quarters | C29: 2023 | D29: October | E29: Roadways | H29: Personal | I29: Small Sized Car | J29: Electric | K29: 283
A30: 23 | B30: Shops, Bank and PO | C30: 2023 | D30: January | E30: Roadways | H30: Personal | I30: Large Sized Car | J30: Diesel | K30: 399
A31: 24 | B31: Residential Areas | C31: 2022 | D31: May | E31: Airways | G31: Long Haul | K31: 5619
A32: 25 | B32: Dhobhighat | C32: 2024 | D32: June | E32: Roadways | H32: Personal | I32: Motorcycle | J32: Petrol/Gasoline | K32: 163
A33: 26 | B33: Lawns and Horticulture | C33: 2022 | D33: May | E33: Roadways | H33: Personal | I33: Large Sized Car | J33: Diesel | K33: 255
A34: 27 | B34: Hostels | C34: 2023 | D34: April | E34: Railways | F34: National Railways | K34: 728
A35: 28 | B35: Others | C35: 2023 | D35: November | E35: Airways | G35: Long Haul | K35: 5000
A36: 29 | B36: Others | C36: 2023 | D36: July | E36: Roadways | H36: Personal | I36: Small Sized Car | J36: Electric | K36: 380
A37: 30 | B37: Shops, Bank and PO | C37: 2022 | D37: September | E37: Railways | F37: Metro | K37: 341
A38: 31 | B38: Academic Area | C38: 2023 | D38: April | E38: Airways | G38: Domestic | K38: 2029

Sheet Offset
B1: Compulsory
B2: Optional
B3: Either fill this
B4: Or this
B5: Don’t Fill This
A6: Enter the serial number | B6: Select the facility name from the dropdown | C6: Enter the year for this data instance | D6: Select the month for this data instance | E6: Enter the Number of Trees in the Facility | F6: Enter the Area Covered by Soil(Sq. KM) | G6: Enter The Area Under Grass(Sq. KM) | H6: Enter the Area Under Water Bodies(Sq. KM)
A7: Sr. No. | B7: Facility Name | C7: Year | D7: Month | E7: Number of Trees | F7: Area Under Soil | G7: Area Under Grass | H7: Area Under Water Bodies
A8: 1 | B8: Residential Areas | C8: 2022 | D8: October | E8: 128 | F8: 0.0171 | G8: 0.0263 | H8: 0.0019
A9: 2 | B9: Residential Areas | C9: 2024 | D9: November | E9: 197 | F9: 0.0228 | G9: 0.005 | H9: 0.0028
A10: 3 | B10: Dhobhighat | C10: 2024 | D10: January | E10: 220 | F10: 0.0405 | G10: 0.024 | H10: 0.0048
A11: 4 | B11: Lawns and Horticulture | C11: 2022 | D11: August | E11: 378 | F11: 0.0058 | G11: 0.0053 | H11: 0.0025
A12: 5 | B12: Lawns and Horticulture | C12: 2024 | D12: August | E12: 173 | F12: 0.0329 | G12: 0.0218 | H12: 0.0014
A13: 6 | B13: Servant's Quarters | C13: 2022 | D13: September | E13: 61 | F13: 0.046 | G13: 0.0116 | H13: 0.0021
A14: 7 | B14: Shops, Bank and PO | C14: 2024 | D14: January | E14: 391 | F14: 0.0448 | G14: 0.0138 | H14: 0.004
A15: 8 | B15: Academic Area | C15: 2022 | D15: April | E15: 111 | F15: 0.0017 | G15: 0.0113 | H15: 0.0021
A16: 9 | B16: Servant's Quarters | C16: 2022 | D16: January | E16: 396 | F16: 0.0114 | G16: 0.0271 | H16: 0.0013
A17: 10 | B17: Academic Area | C17: 2022 | D17: September | E17: 446 | F17: 0.0478 | G17: 0.0125 | H17: 0.004
A18: 11 | B18: Others | C18: 2022 | D18: September | E18: 61 | F18: 0.0235 | G18: 0.0202 | H18: 0.0016
A19: 12 | B19: Lawns and Horticulture | C19: 2024 | D19: November | E19: 403 | F19: 0.0089 | G19: 0.0153 | H19: 0.0016
... A38: 31 | B38: Residential Areas | C38: 2023 | D38: November | E38: 27 | F38: 0.0266 | G38: 0.0126 | H38: 0.0014

Sheet Secondary Data
B1: Compulsory
B2: Optional
B3: Either fill this
B4: Or this
B5: Don’t Fill This
A6: Enter the serial number | B6: Select the facility name from the dropdown | C6: Enter the year for this data instance | D6: Select the month for this data instance | E6: Select the category of purchased goods / services | F6: Select the unit of spend | G6: Enter the amount spent | H6: Auto-calculated | I6: Auto-calculated = Amount Spent x Emission Factor | J6: Auto-calculated = kg / 1000 | M6: Category | N6: Emission Factor (kgCO2e / INR '000)
A7: Sr. No. | B7: Facility Name | C7: Year | D7: Month | E7: Category | F7: Unit | G7: Amount Spent | H7: Emission Factor | I7: CO2e Emissions (kg) | J7: CO2e Emissions (tonnes) | M7: Food & Beverages | N7: 8.5
A8: 1 | B8: Health Centre | C8: 2022 | D8: December | E8: Construction Materials | F8: INR '000 spent | G8: 1398 | H8: =IFERROR(INDEX($N$7:$N$16,MATCH(E8,$M$7:$M$16,0)),"") -> 18 | I8: =IF(OR(G8="",H8=""),"",G8*H8) -> 25164 | J8: =IF(I8="","",I8/1000) -> 25.164 | M8: Paper & Stationery | N8: 12
A9: 2 | B9: Residential Areas | C9: 2023 | D9: August | E9: Food & Beverages | F9: INR '000 spent | G9: 130 | H9: =IFERROR(INDEX($N$7:$N$16,MATCH(E9,$M$7:$M$16,0)),"") -> 8.5 | I9: =IF(OR(G9="",H9=""),"",G9*H9) -> 1105 | J9: =IF(I9="","",I9/1000) -> 1.105 | M9: Computers & IT Equipment | N9: 15.5
A10: 3 | B10: Hostels | C10: 2023 | D10: March | E10: Clothing & Textiles | F10: INR '000 spent | G10: 1121 | H10: =IFERROR(INDEX($N$7:$N$16,MATCH(E10,$M$7:$M$16,0)),"") -> 9.5 | I10: =IF(OR(G10="",H10=""),"",G10*H10) -> 10649.5 | J10: =IF(I10="","",I10/1000) -> 10.6495 | M10: Furniture & Fixtures | N10: 10
A11: 4 | B11: Residential Areas | C11: 2023 | D11: January | E11: Recreation & Culture | F11: INR '000 spent | G11: 79 | H11: =IFERROR(INDEX($N$7:$N$16,MATCH(E11,$M$7:$M$16,0)),"") -> 6.5 | I11: =IF(OR(G11="",H11=""),"",G11*H11) -> 513.5 | J11: =IF(I11="","",I11/1000) -> 0.5135 | M11: Clothing & Textiles | N11: 9.5
A12: 5 | B12: Visitor's Hostel | C12: 2024 | D12: January | E12: Financial & Professional Services | F12: INR '000 spent | G12: 965 | H12: =IFERROR(INDEX($N$7:$N$16,MATCH(E12,$M$7:$M$16,0)),"") -> 3 | I12: =IF(OR(G12="",H12=""),"",G12*H12) -> 2895 | J12: =IF(I12="","",I12/1000) -> 2.895 | M12: Pharmaceuticals & Lab Supplies | N12: 11
A13: 6 | B13: Health Centre | C13: 2023 | D13: March | E13: Pharmaceuticals & Lab Supplies | F13: INR '000 spent | G13: 679 | H13: =IFERROR(INDEX($N$7:$N$16,MATCH(E13,$M$7:$M$16,0)),"") -> 11 | I13: =IF(OR(G13="",H13=""),"",G13*H13) -> 7469 | J13: =IF(I13="","",I13/1000) -> 7.469 | M13: Construction Materials | N13: 18
A14: 7 | B14: Dhobhighat | C14: 2022 | D14: August | E14: Pharmaceuticals & Lab Supplies | F14: INR '000 spent | G14: 279 | H14: =IFERROR(INDEX($N$7:$N$16,MATCH(E14,$M$7:$M$16,0)),"") -> 11 | I14: =IF(OR(G14="",H14=""),"",G14*H14) -> 3069 | J14: =IF(I14="","",I14/1000) -> 3.069 | M14: Hotels, Travel & Conferences | N14: 14
A15: 8 | B15: Hostels | C15: 2024 | D15: September | E15: Paper & Stationery | F15: INR '000 spent | G15: 886 | H15: =IFERROR(INDEX($N$7:$N$16,MATCH(E15,$M$7:$M$16,0)),"") -> 12 | I15: =IF(OR(G15="",H15=""),"",G15*H15) -> 10632 | J15: =IF(I15="","",I15/1000) -> 10.632 | M15: Financial & Professional Services | N15: 3
A16: 9 | B16: Visitor's Hostel | C16: 2022 | D16: January | E16: Food & Beverages | F16: INR '000 spent | G16: 1370 | H16: =IFERROR(INDEX($N$7:$N$16,MATCH(E16,$M$7:$M$16,0)),"") -> 8.5 | I16: =IF(OR(G16="",H16=""),"",G16*H16) -> 11645 | J16: =IF(I16="","",I16/1000) -> 11.645 | M16: Recreation & Culture | N16: 6.5
A17: 10 | B17: Hostels | C17: 2023 | D17: March | E17: Pharmaceuticals & Lab Supplies | F17: INR '000 spent | G17: 334 | H17: =IFERROR(INDEX($N$7:$N$16,MATCH(E17,$M$7:$M$16,0)),"") -> 11 | I17: =IF(OR(G17="",H17=""),"",G17*H17) -> 3674 | J17: =IF(I17="","",I17/1000) -> 3.674
A18: 11 | B18: Lawns and Horticulture | C18: 2024 | D18: February | E18: Clothing & Textiles | F18: INR '000 spent | G18: 713 | H18: =IFERROR(INDEX($N$7:$N$16,MATCH(E18,$M$7:$M$16,0)),"") -> 9.5 | I18: =IF(OR(G18="",H18=""),"",G18*H18) -> 6773.5 | J18: =IF(I18="","",I18/1000) -> 6.7735
A19: 12 | B19: Academic Area | C19: 2024 | D19: June | E19: Hotels, Travel & Conferences | F19: INR '000 spent | G19: 1395 | H19: =IFERROR(INDEX($N$7:$N$16,MATCH(E19,$M$7:$M$16,0)),"") -> 14 | I19: =IF(OR(G19="",H19=""),"",G19*H19) -> 19530 | J19: =IF(I19="","",I19/1000) -> 19.53
A20: 13 | B20: Others | C20: 2024 | D20: July | E20: Recreation & Culture | F20: INR '000 spent | G20: 54 | H20: =IFERROR(INDEX($N$7:$N$16,MATCH(E20,$M$7:$M$16,0)),"") -> 6.5 | I20: =IF(OR(G20="",H20=""),"",G20*H20) -> 351 | J20: =IF(I20="","",I20/1000) -> 0.351
A21: 14 | B21: Dhobhighat | C21: 2024 | D21: May | E21: Pharmaceuticals & Lab Supplies | F21: INR '000 spent | G21: 506 | H21: =IFERROR(INDEX($N$7:$N$16,MATCH(E21,$M$7:$M$16,0)),"") -> 11 | I21: =IF(OR(G21="",H21=""),"",G21*H21) -> 5566 | J21: =IF(I21="","",I21/1000) -> 5.566
A22: 15 | B22: Others | C22: 2022 | D22: February | E22: Computers & IT Equipment | F22: INR '000 spent | G22: 1026 | H22: =IFERROR(INDEX($N$7:$N$16,MATCH(E22,$M$7:$M$16,0)),"") -> 15.5 | I22: =IF(OR(G22="",H22=""),"",G22*H22) -> 15903 | J22: =IF(I22="","",I22/1000) -> 15.903
A23: 16 | B23: Shops, Bank and PO | C23: 2024 | D23: January | E23: Food & Beverages | F23: INR '000 spent | G23: 447 | H23: =IFERROR(INDEX($N$7:$N$16,MATCH(E23,$M$7:$M$16,0)),"") -> 8.5 | I23: =IF(OR(G23="",H23=""),"",G23*H23) -> 3799.5 | J23: =IF(I23="","",I23/1000) -> 3.7995
A24: 17 | B24: Servant's Quarters | C24: 2024 | D24: May | E24: Food & Beverages | F24: INR '000 spent | G24: 508 | H24: =IFERROR(INDEX($N$7:$N$16,MATCH(E24,$M$7:$M$16,0)),"") -> 8.5 | I24: =IF(OR(G24="",H24=""),"",G24*H24) -> 4318 | J24: =IF(I24="","",I24/1000) -> 4.318
A25: 18 | B25: Hostels | C25: 2023 | D25: March | E25: Computers & IT Equipment | F25: INR '000 spent | G25: 400 | H25: =IFERROR(INDEX($N$7:$N$16,MATCH(E25,$M$7:$M$16,0)),"") -> 15.5 | I25: =IF(OR(G25="",H25=""),"",G25*H25) -> 6200 | J25: =IF(I25="","",I25/1000) -> 6.2
A26: 19 | B26: Servant's Quarters | C26: 2024 | D26: March | E26: Financial & Professional Services | F26: INR '000 spent | G26: 781 | H26: =IFERROR(INDEX($N$7:$N$16,MATCH(E26,$M$7:$M$16,0)),"") -> 3 | I26: =IF(OR(G26="",H26=""),"",G26*H26) -> 2343 | J26: =IF(I26="","",I26/1000) -> 2.343
A27: 20 | B27: Health Centre | C27: 2024 | D27: June | E27: Paper & Stationery | F27: INR '000 spent | G27: 1229 | H27: =IFERROR(INDEX($N$7:$N$16,MATCH(E27,$M$7:$M$16,0)),"") -> 12 | I27: =IF(OR(G27="",H27=""),"",G27*H27) -> 14748 | J27: =IF(I27="","",I27/1000) -> 14.748
A28: 21 | B28: Lawns and Horticulture | C28: 2022 | D28: September | E28: Furniture & Fixtures | F28: INR '000 spent | G28: 527 | H28: =IFERROR(INDEX($N$7:$N$16,MATCH(E28,$M$7:$M$16,0)),"") -> 10 | I28: =IF(OR(G28="",H28=""),"",G28*H28) -> 5270 | J28: =IF(I28="","",I28/1000) -> 5.27
... A38: 31 | B38: Schools | C38: 2022 | D38: April | E38: Financial & Professional Services | F38: INR '000 spent | G38: 1138 | H38: =IFERROR(INDEX($N$7:$N$16,MATCH(E38,$M$7:$M$16,0)),"") -> 3 | I38: =IF(OR(G38="",H38=""),"",G38*H38) -> 3414 | J38: =IF(I38="","",I38/1000) -> 3.414
E39: TOTAL CARBON FOOTPRINT (Secondary Data) | I39: =SUM(I8:I38) -> 251867.5 | J39: =SUM(J8:J38) -> 251.8675

Sheet Summary
A1: Total Carbon Footprint
A2: All calculations below are formulas that read directly from the data tabs; nothing on the data tabs was altered.
A4: Emission Factor Reference Tables (rough / illustrative) | E4: Category Totals
A5: Fossil Fuel - by Fuel Type | B5: Factor | E5: Category | F5: tCO2e
A6: Petrol/Gasoline (kg CO2e/kg) | B6: 2.3 | E6: Fossil Fuel | F6: =(SUMPRODUCT(('Fossil Fuel'!$E$8:$E$38="Petrol/Gasoline")*'Fossil Fuel'!$G$8:$G$38)*B6+SUMPRODUCT(('Fossil Fuel'!$E$8:$E$38="Diesel")*'Fossil Fuel'!$G$8:$G$38)*B7+SUMPRODUCT(('Fossil Fuel'!$E$8:$E$38="LPG")*'Fossil Fuel'!$G$8:$G$38)*B8+SUMPRODUCT(('Fossil Fuel'!$E$8:$E$38="PNG")*'Fossil Fuel'!$G$8:$G$38)*B9+SUMPRODUCT(('Fossil Fuel'!$E$8:$E$38="CNG")*'Fossil Fuel'!$G$8:$G$38)*B10)/1000 -> 45.39535
A7: Diesel (kg CO2e/kg) | B7: 2.68 | E7: Fugitive | F7: =(SUMPRODUCT((Fugitive!$E$8:$E$38="Domestic Refrigeration")*Fugitive!$F$8:$F$38)*B13+SUMPRODUCT((Fugitive!$E$8:$E$38="Commercial Refrigeration")*Fugitive!$F$8:$F$38)*B14+SUMPRODUCT((Fugitive!$E$8:$E$38="Industrial Refrigeration")*Fugitive!$F$8:$F$38)*B15+SUMPRODUCT((Fugitive!$E$8:$E$38="Residential and Commercial A/Cs ")*Fugitive!$F$8:$F$38)*B16)/1000 -> 77.985
A8: LPG (kg CO2e/kg) | B8: 2.98 | E8: Electricity | F8: =(SUMPRODUCT((Electricity!$E$7:$E$37="Coal/Thermal")*Electricity!$H$7:$H$37)*B19+SUMPRODUCT((Electricity!$E$7:$E$37="Solar")*Electricity!$H$7:$H$37)*B20)/1000 -> 161.05183
A9: PNG (kg CO2e/kg) | B9: 2.75 | E9: Water | F9: =(SUMPRODUCT((Water!$E$8:$E$38="Supplied Water")*Water!$H$8:$H$38)*B23+SUMPRODUCT((Water!$E$8:$E$38="Treated Water")*Water!$H$8:$H$38)*B24)/1000 -> 11.79245
A10: CNG (kg CO2e/kg) | B10: 2.7 | E10: Waste | F10: =(SUMPRODUCT((Waste!$F$8:$F$38="Landfills")*Waste!$H$8:$H$38)*B27+SUMPRODUCT((Waste!$F$8:$F$38="Combustion")*Waste!$H$8:$H$38)*B28+SUMPRODUCT((Waste!$F$8:$F$38="Recycling")*Waste!$H$8:$H$38)*B29+SUMPRODUCT((Waste!$F$8:$F$38="Composting")*Waste!$H$8:$H$38)*B30)/1000 -> 8.4439
E11: Travel | F11: =(SUMPRODUCT((Travel!$E$8:$E$38="Airways")*(Travel!$G$8:$G$38="Domestic")*Travel!$K$8:$K$38)*B33+SUMPRODUCT((Travel!$E$8:$E$38="Airways")*(Travel!$G$8:$G$38="Short Haul")*Travel!$K$8:$K$38)*B34+SUMPRODUCT((Travel!$E$8:$E$38="Airways")*(Travel!$G$8:$G$38="Long Haul")*Travel!$K$8:$K$38)*B35+SUMPRODUCT((Travel!$E$8:$E$38="Airways")*(Travel!$G$8:$G$38="International")*Travel!$K$8:$K$38)*B36+SUMPRODUCT((Travel!$E$8:$E$38="Railways")*(Travel!$F$8:$F$38="National Railways")*Travel!$K$8:$K$38)*B37+SUMPRODUCT((Travel!$E$8:$E$38="Railways")*(Travel!$F$8:$F$38="Metro")*Travel!$K$8:$K$38)*B38+SUMPRODUCT((Travel!$E$8:$E$38="Roadways")*(Travel!$I$8:$I$38="Bus")*Travel!$K$8:$K$38)*B39+SUMPRODUCT((Travel!$E$8:$E$38="Roadways")*(Travel!$I$8:$I$38="Taxi")*Travel!$K$8:$K$38)*B40+SUMPRODUCT((Travel!$E$8:$E$38="Roadways")*(Travel!$I$8:$I$38="Small Sized Car")*Travel!$K$8:$K$38)*B41+SUMPRODUCT((Travel!$E$8:$E$38="Roadways")*(Travel!$I$8:$I$38="Medium Sized Car")*Travel!$K$8:$K$38)*B42+SUMPRODUCT((Travel!$E$8:$E$38="Roadways")*(Travel!$I$8:$I$38="Large Sized Car")*Travel!$K$8:$K$38)*B43+SUMPRODUCT((Travel!$E$8:$E$38="Roadways")*(Travel!$I$8:$I$38="Motorcycle")*Travel!$K$8:$K$38)*B44)/1000 -> 5.7017
A12: Fugitive - by Application Type | B12: Factor | E12: Secondary Data | F12: ='Secondary Data'!J39 -> 251.8675
A13: Domestic Refrigeration (kg CO2e/unit) | B13: 45 | E13: Subtotal - Gross Emissions | F13: =SUM(F6:F12) -> 562.23773
A14: Commercial Refrigeration (kg CO2e/unit) | B14: 320
A15: Industrial Refrigeration (kg CO2e/unit) | B15: 850 | E15: Less: Carbon Offset (sequestration) | F15: =-((SUM(Offset!$E$8:$E$38)*B47+SUM(Offset!$F$8:$F$38)*B48+SUM(Offset!$G$8:$G$38)*B49+SUM(Offset!$H$8:$H$38)*B50)/1000) -> -243.656
A16: Residential and Commercial A/Cs (kg CO2e/unit) | B16: 180
E17: NET TOTAL CARBON FOOTPRINT | F17: =F13+F15 -> 318.58173
A18: Electricity - by Source Type | B18: Factor
A19: Coal/Thermal (kg CO2e/kWh) | B19: 0.82
A20: Solar (kg CO2e/kWh) | B20: 0.05
A22: Water - by Type | B22: Factor
A23: Supplied Water (kg CO2e/m3) | B23: 0.35
A24: Treated Water (kg CO2e/m3) | B24: 0.25
A26: Waste - by Treatment Type | B26: Factor
A27: Landfills (kg CO2e/kg) | B27: 1.8
A28: Combustion (kg CO2e/kg) | B28: 1.2
A29: Recycling (kg CO2e/kg) | B29: 0.3
A30: Composting (kg CO2e/kg) | B30: 0.25
A32: Travel - by Mode | B32: Factor
A33: Airways - Domestic (kg CO2e/km) | B33: 0.18
A34: Airways - Short Haul (kg CO2e/km) | B34: 0.15
A35: Airways - Long Haul (kg CO2e/km) | B35: 0.11
A36: Airways - International (kg CO2e/km) | B36: 0.11
A37: Railways - National Railways (kg CO2e/km) | B37: 0.04
A38: Railways - Metro (kg CO2e/km) | B38: 0.03
A39: Roadways - Bus (kg CO2e/km) | B39: 0.05
A40: Roadways - Taxi (kg CO2e/km) | B40: 0.15
A41: Roadways - Small Car (kg CO2e/km) | B41: 0.15
A42: Roadways - Medium Car (kg CO2e/km) | B42: 0.19
A43: Roadways - Large Car (kg CO2e/km) | B43: 0.25
A44: Roadways - Motorcycle (kg CO2e/km) | B44: 0.09
...

Sheet Footprint
A1: Your Carbon Footprint
A2: Tick a category to include it in your footprint total. Values are pulled live from the Summary sheet; nothing on the data tabs is altered.
B4: Include | C4: Category | D4: tCO2e
A5: =IF(B5,"☑","☐") -> ☑ | B5: =TRUE() -> TRUE | C5: Fossil Fuel | D5: =Summary!F6 -> 45.39535
A6: =IF(B6,"☑","☐") -> ☑ | B6: =TRUE() -> TRUE | C6: Fugitive | D6: =Summary!F7 -> 77.985
A7: =IF(B7,"☑","☐") -> ☑ | B7: =TRUE() -> TRUE | C7: Electricity | D7: =Summary!F8 -> 161.05183
A8: =IF(B8,"☑","☐") -> ☑ | B8: =TRUE() -> TRUE | C8: Water | D8: =Summary!F9 -> 11.79245
A9: =IF(B9,"☑","☐") -> ☑ | B9: =TRUE() -> TRUE | C9: Waste | D9: =Summary!F10 -> 8.4439
A10: =IF(B10,"☑","☐") -> ☑ | B10: =TRUE() -> TRUE | C10: Travel | D10: =Summary!F11 -> 5.7017
A11: =IF(B11,"☑","☐") -> ☑ | B11: =TRUE() -> TRUE | C11: Secondary Data | D11: =Summary!F12 -> 251.8675
C12: Total (selected categories) | D12: =SUMPRODUCT(B5:B11*D5:D11) -> 562.23773
A14: ="Total To Offset = "&TEXT(D12,"#,##0.00")&" metric tons of CO2e" -> Total To Offset = 562.24 metric tons of CO2e
A16: Comparison Benchmarks (metric tons CO2e / year)
A17: Country Average | C17: 1.9 | D17: e.g. per-capita average for your country — edit to match your context
A18: World Average | C18: 4.86 | D18: Source: Global Carbon Project, world average per-capita footprint
A19: Reduction Target | C19: 0 | D19: Worldwide target to combat climate change
A21: Footprint Comparison | B21: tCO2e
A22: Your Footprint | B22: =D12 -> 562.23773
A23: Country Average | B23: =C17 -> 1.9
A24: World Average | B24: =C18 -> 4.86
A25: Reduction Target | B25: =C19 -> 0
A37: ="• Your footprint is "&TEXT(D12,"#,##0.00")&" metric tons per year" -> • Your footprint is 562.24 metric tons per year
A38: ="• The average footprint for your Country Average benchmark is "&TEXT(C17,"#,##0.00")&" metric tons" -> • The average footprint for your Country Average benchmark is 1.90 metric tons
A39: ="• The average worldwide carbon footprint is about "&TEXT(C18,"#,##0.00")&" metric tons" -> • The average worldwide carbon footprint is about 4.86 metric tons
A40: ="• The worldwide target to combat climate change is "&TEXT(C19,"#,##0.00")&" metric tons" -> • The worldwide target to combat climate change is 0.00 metric tons

Sheet Dropdowns
A1: Household Residue | B1: Commercial and Industrial Waste | C1: Food and Drink Waste | D1: Garden Waste | E1: Petrol/Gasoline | F1: LPG | G1: PNG | H1: Diesel | I1: CNG
A2: Landfills | B2: Landfills | C2: Landfills | D2: Landfills | E2: tonne | F2: tonne | G2: tonne | H2: tonne | I2: tonne
A3: Combustion | B3: Combustion | C3: Combustion | D3: Combustion | E3: kg | F3: kg | G3: kg | H3: kg | I3: kg
A4: Recycling | B4: Recycling | C4: Recycling | D4: Recycling | E4: cubic metre | F4: litre | G4: cubic metre | H4: litre | I4: cubic metre
C5: Composting | D5: Composting
A6: Public | B6: Personal
A7: Bus | B7: Small Sized Car
A8: Taxi | B8: Medium Sized Car
B9: Large Sized Car
B10: Motorcycle
B13: Small Sized Car | C13: Medium Sized Car | D13: Large Sized Car
B14: Petrol/Gasoline | C14: Petrol/Gasoline | D14: Petrol/Gasoline
B15: Diesel | C15: Diesel | D15: Diesel
B16: Electric | C16: Electric | D16: Electric
C17: CNG | D17: CNG
